Workbook

Sheet Initial Results
A1: All Papers | B1: Erin | C1: Tanim | D1: Reason for Disagreement (E) | E1: Reason for Disagreement (T) | F1: Erin Accepted | G1: Tanim Accepted | J1: Legend:
A2: Preparing medical first responders for crises: a systematic literature review of disaster training programs and their effectiveness | B2: =IF(COUNTIF('Erin Accepted'!B:B, TRIM(SUBSTITUTE(A2, " ", ""))) > 0, "O", "X") -> X | C2: =IF(COUNTIF('Tanim Accepted'!B:B, TRIM(SUBSTITUTE(A2, " ", ""))) > 0, "O", "X") -> O | F2: =COUNTIF(B:B, "O") -> 84 | G2: =COUNTIF(C:C, "O") -> 119 | J2: Accept: O
A3: A Next-Generation Augmented Reality Platform for Mass Casualty Incidents (MCI) | B3: =IF(COUNTIF('Erin Accepted'!B:B, TRIM(SUBSTITUTE(A3, " ", ""))) > 0, "O", "X") -> X | C3: =IF(COUNTIF('Tanim Accepted'!B:B, TRIM(SUBSTITUTE(A3, " ", ""))) > 0, "O", "X") -> O | J3: Reject: X
A4: Ajna: A Wearable Shared Perception System for Extreme Sensemaking | B4: =IF(COUNTIF('Erin Accepted'!B:B, TRIM(SUBSTITUTE(A4, " ", ""))) > 0, "O", "X") -> X | C4: =IF(COUNTIF('Tanim Accepted'!B:B, TRIM(SUBSTITUTE(A4, " ", ""))) > 0, "O", "X") -> O
A5: Leveraging Augmented Reality for Improved Situational Awareness During UAV-Driven Search and Rescue Missions | B5: =IF(COUNTIF('Erin Accepted'!B:B, TRIM(SUBSTITUTE(A5, " ", ""))) > 0, "O", "X") -> X | C5: =IF(COUNTIF('Tanim Accepted'!B:B, TRIM(SUBSTITUTE(A5, " ", ""))) > 0, "O", "X") -> O
A6: Research on the application of AR in the safety inspection of opening and closing stations | B6: =IF(COUNTIF('Erin Accepted'!B:B, TRIM(SUBSTITUTE(A6, " ", ""))) > 0, "O", "X") -> X | C6: =IF(COUNTIF('Tanim Accepted'!B:B, TRIM(SUBSTITUTE(A6, " ", ""))) > 0, "O", "X") -> O
A7: Blaze Buster Augmented Reality Usability Evaluation | B7: =IF(COUNTIF('Erin Accepted'!B:B, TRIM(SUBSTITUTE(A7, " ", ""))) > 0, "O", "X") -> X | C7: =IF(COUNTIF('Tanim Accepted'!B:B, TRIM(SUBSTITUTE(A7, " ", ""))) > 0, "O", "X") -> O
A8: A Fire Reconnaissance Robot Based on SLAM Position, Thermal Imaging Technologies, and AR Display | B8: =IF(COUNTIF('Erin Accepted'!B:B, TRIM(SUBSTITUTE(A8, " ", ""))) > 0, "O", "X") -> X | C8: =IF(COUNTIF('Tanim Accepted'!B:B, TRIM(SUBSTITUTE(A8, " ", ""))) > 0, "O", "X") -> O
A9: Design of a Mixed Reality System for Simulating Indoor Disaster Rescue | B9: =IF(COUNTIF('Erin Accepted'!B:B, TRIM(SUBSTITUTE(A9, " ", ""))) > 0, "O", "X") -> O | C9: =IF(COUNTIF('Tanim Accepted'!B:B, TRIM(SUBSTITUTE(A9, " ", ""))) > 0, "O", "X") -> O
A10: Method and application of information sharing throughout the emergency rescue process based on 5G and AR wearable devices | B10: =IF(COUNTIF('Erin Accepted'!B:B, TRIM(SUBSTITUTE(A10, " ", ""))) > 0, "O", "X") -> O | C10: =IF(COUNTIF('Tanim Accepted'!B:B, TRIM(SUBSTITUTE(A10, " ", ""))) > 0, "O", "X") -> O
A11: Mobile Augmented Reality Techniques for Emergency Response | B11: =IF(COUNTIF('Erin Accepted'!B:B, TRIM(SUBSTITUTE(A11, " ", ""))) > 0, "O", "X") -> O | C11: =IF(COUNTIF('Tanim Accepted'!B:B, TRIM(SUBSTITUTE(A11, " ", ""))) > 0, "O", "X") -> O
A12: Tangible Immersive Trauma Simulation: Is Mixed Reality the next Level of Medical Skills Training? | B12: =IF(COUNTIF('Erin Accepted'!B:B, TRIM(SUBSTITUTE(A12, " ", ""))) > 0, "O", "X") -> X | C12: =IF(COUNTIF('Tanim Accepted'!B:B, TRIM(SUBSTITUTE(A12, " ", ""))) > 0, "O", "X") -> O
A13: Training emergency responders through augmented reality mobile interfaces | B13: =IF(COUNTIF('Erin Accepted'!B:B, TRIM(SUBSTITUTE(A13, " ", ""))) > 0, "O", "X") -> O | C13: =IF(COUNTIF('Tanim Accepted'!B:B, TRIM(SUBSTITUTE(A13, " ", ""))) > 0, "O", "X") -> O
A14: Eliciting Requirements for a Multisensory EXtended Reality Platform for Training and Informal Learning | B14: =IF(COUNTIF('Erin Accepted'!B:B, TRIM(SUBSTITUTE(A14, " ", ""))) > 0, "O", "X") -> X | C14: =IF(COUNTIF('Tanim Accepted'!B:B, TRIM(SUBSTITUTE(A14, " ", ""))) > 0, "O", "X") -> O
A15: Design of Intelligent Firefighter Helmet Based on AR Technology | B15: =IF(COUNTIF('Erin Accepted'!B:B, TRIM(SUBSTITUTE(A15, " ", ""))) > 0, "O", "X") -> O | C15: =IF(COUNTIF('Tanim Accepted'!B:B, TRIM(SUBSTITUTE(A15, " ", ""))) > 0, "O", "X") -> O
... A1752: A Mixed-Methods Approach for the Evaluation of Situational Awareness and User Experience with Augmented Reality Technologies | B1752: =IF(COUNTIF('Erin Accepted'!B:B, TRIM(SUBSTITUTE(A1752, " ", ""))) > 0, "O", "X") -> O | C1752: =IF(COUNTIF('Tanim Accepted'!B:B, TRIM(SUBSTITUTE(A1752, " ", ""))) > 0, "O", "X") -> X

Sheet Erin Accepted
A1: Evaluation of an augmented reality platform for austere surgical telementoring: a randomized controlled crossover study in cricothyroidotomies | B1: =TRIM(SUBSTITUTE(A1," ","")) -> Evaluationofanaugmentedrealityplatformforausteresurgicaltelementoring:arandomizedcontrolledcrossoverstudyincricothyroidotomies
A2: A 'mixed reality' simulator concept for future Medical Emergency Response Team training | B2: =TRIM(SUBSTITUTE(A2," ","")) -> A'mixedreality'simulatorconceptforfutureMedicalEmergencyResponseTeamtraining
A3: An augmented reality system for health care provision via telematics support | B3: =TRIM(SUBSTITUTE(A3," ","")) -> Anaugmentedrealitysystemforhealthcareprovisionviatelematicssupport
A4: Technical support by smart glasses during a mass casualty incident: A randomized controlled simulation trial on technically assisted triage and telemedical app use in disaster medicine | B4: =TRIM(SUBSTITUTE(A4," ","")) -> Technicalsupportbysmartglassesduringamasscasualtyincident:Arandomizedcontrolledsimulationtrialontechnicallyassistedtriageandtelemedicalappuseindisastermedicine
A5: Usability and reliability of smart glasses for secondary triage during mass casualty incidents | B5: =TRIM(SUBSTITUTE(A5," ","")) -> Usabilityandreliabilityofsmartglassesforsecondarytriageduringmasscasualtyincidents
A6: Head-Worn Displays for Emergency Medical Services Staff | B6: =TRIM(SUBSTITUTE(A6," ","")) -> Head-WornDisplaysforEmergencyMedicalServicesStaff
A7: CPR Emergency Assistance Through Mixed Reality Communication | B7: =TRIM(SUBSTITUTE(A7," ","")) -> CPREmergencyAssistanceThroughMixedRealityCommunication
A8: Telementorship in Underway Naval Operations: Leveraging Operational Virtual Health for Tactical Combat Casualty Care | B8: =TRIM(SUBSTITUTE(A8," ","")) -> TelementorshipinUnderwayNavalOperations:LeveragingOperationalVirtualHealthforTacticalCombatCasualtyCare
A9: Augmented Reality Technology to Facilitate Proficiency in Emergency Medical Procedures | B9: =TRIM(SUBSTITUTE(A9," ","")) -> AugmentedRealityTechnologytoFacilitateProficiencyinEmergencyMedicalProcedures
A10: Augmented reality training, command and control framework for first responders | B10: =TRIM(SUBSTITUTE(A10," ","")) -> Augmentedrealitytraining,commandandcontrolframeworkforfirstresponders
A11: Next generation emergency management common operating picture software/systems (COPSS) | B11: =TRIM(SUBSTITUTE(A11," ","")) -> Nextgenerationemergencymanagementcommonoperatingpicturesoftware/systems(COPSS)
A12: Radiological Incident System using Augmented Reality (RISAR) | B12: =TRIM(SUBSTITUTE(A12," ","")) -> RadiologicalIncidentSystemusingAugmentedReality(RISAR)
... A84: Mobile AR Application for Navigation and Emergency Response | B84: =TRIM(SUBSTITUTE(A84," ","")) -> MobileARApplicationforNavigationandEmergencyResponse

Sheet Tanim Accepted
A1: User-CenteredDesignandEvaluationofARTTS:anAugmentedRealityTriageToolSuiteforMassCasualtyIncidents | B1: =TRIM(SUBSTITUTE(A1," ","")) -> User-CenteredDesignandEvaluationofARTTS:anAugmentedRealityTriageToolSuiteforMassCasualtyIncidents
A2: CreatingInformalLearningandFirstResponderTrainingXRExperienceswiththeImmersiveDeck | B2: =TRIM(SUBSTITUTE(A2," ","")) -> CreatingInformalLearningandFirstResponderTrainingXRExperienceswiththeImmersiveDeck
A3: AnAugmentedRealityFrameworkforFirstResponders:theRESPOND-Aprojectapproach | B3: =TRIM(SUBSTITUTE(A3," ","")) -> AnAugmentedRealityFrameworkforFirstResponders:theRESPOND-Aprojectapproach
A4: EnhancingDisasterResponseTrainingthroughImmersiveAR/VRSimulations | B4: =TRIM(SUBSTITUTE(A4," ","")) -> EnhancingDisasterResponseTrainingthroughImmersiveAR/VRSimulations
A5: Demo:CollaborativeMixed-Reality-BasedFirefighterTraining | B5: =TRIM(SUBSTITUTE(A5," ","")) -> Demo:CollaborativeMixed-Reality-BasedFirefighterTraining
A6: TrainandEquipFirefighterswithCognitiveVirtualandAugmentedReality | B6: =TRIM(SUBSTITUTE(A6," ","")) -> TrainandEquipFirefighterswithCognitiveVirtualandAugmentedReality
A7: MiRTE:MixedRealityTriageandEvacuationgameforMassCasualtyinformationsystemsdesign,testingandtraining | B7: =TRIM(SUBSTITUTE(A7," ","")) -> MiRTE:MixedRealityTriageandEvacuationgameforMassCasualtyinformationsystemsdesign,testingandtraining
A8: RedCrossTriageAppDesignforAugmentedRealityGlasses | B8: =TRIM(SUBSTITUTE(A8," ","")) -> RedCrossTriageAppDesignforAugmentedRealityGlasses
A9: VR[weare]Training-WorkshoponCollaborativeVirtualTrainingforChallengingContexts | B9: =TRIM(SUBSTITUTE(A9," ","")) -> VR[weare]Training-WorkshoponCollaborativeVirtualTrainingforChallengingContexts
A10: FirstResponders'TakeonTechnology:ADeepDiveintoMobileandARInterfacePreferences. | B10: =TRIM(SUBSTITUTE(A10," ","")) -> FirstResponders'TakeonTechnology:ADeepDiveintoMobileandARInterfacePreferences.
A11: XRfor FirstResponders:Concepts,Challengesand FuturePotentialof ImmersiveTraining | B11: =TRIM(SUBSTITUTE(A11," ","")) -> XRfor FirstResponders:Concepts,Challengesand FuturePotentialof ImmersiveTraining
A12: SimulatingNext-GenerationUserInterfacesforLawEnforcementTrafficStops | B12: =TRIM(SUBSTITUTE(A12," ","")) -> SimulatingNext-GenerationUserInterfacesforLawEnforcementTrafficStops
... A119: Towards an immersive virtual reality training system for CBRN disaster preparedness | B119: =TRIM(SUBSTITUTE(A119," ","")) -> TowardsanimmersivevirtualrealitytrainingsystemforCBRNdisasterpreparedness

Sheet Discussion Results
A1: All Papers | B1: Erin | C1: Tanim | D1: Agreement | E1: Reason for Disagreement (E) | F1: Reason for Disagreement (T) | G1: Erin Accepted | H1: Tanim Accepted | I1: Final Decision | J1: Final Notes | K1: Legend:
A2: Ajna: A Wearable Shared Perception System for Extreme Sensemaking | B2: Accept | C2: =IF(COUNTIF('Tanim Accepted'!B:B, TRIM(SUBSTITUTE(A2, " ", ""))) > 0, "Accept", "Reject") -> Accept | D2: =B2=C2 -> TRUE | E2: Came to consensus
A3: Leveraging Augmented Reality for Improved Situational Awareness During UAV-Driven Search and Rescue Missions | B3: Accept | C3: =IF(COUNTIF('Tanim Accepted'!B:B, TRIM(SUBSTITUTE(A3, " ", ""))) > 0, "Accept", "Reject") -> Accept | D3: =B3=C3 -> TRUE | E3: Came to consensus
A4: A Fire Reconnaissance Robot Based on SLAM Position, Thermal Imaging Technologies, and AR Display | B4: Accept | C4: =IF(COUNTIF('Tanim Accepted'!B:B, TRIM(SUBSTITUTE(A4, " ", ""))) > 0, "Accept", "Reject") -> Accept | D4: =B4=C4 -> TRUE | E4: Raise for Group Discussion | F4: Raise for Group Discussion | I4: Accept | J4: Paper to be included in final data, elements need to be addressed in paper
A5: Design of a Mixed Reality System for Simulating Indoor Disaster Rescue | B5: =IF(COUNTIF('Erin Accepted'!B:B, TRIM(SUBSTITUTE(A5, " ", ""))) > 0, "Accept", "Reject") -> Accept | C5: =IF(COUNTIF('Tanim Accepted'!B:B, TRIM(SUBSTITUTE(A5, " ", ""))) > 0, "Accept", "Reject") -> Accept | D5: =B5=C5 -> TRUE
A6: Method and application of information sharing throughout the emergency rescue process based on 5G and AR wearable devices | B6: =IF(COUNTIF('Erin Accepted'!B:B, TRIM(SUBSTITUTE(A6, " ", ""))) > 0, "Accept", "Reject") -> Accept | C6: =IF(COUNTIF('Tanim Accepted'!B:B, TRIM(SUBSTITUTE(A6, " ", ""))) > 0, "Accept", "Reject") -> Accept | D6: =B6=C6 -> TRUE
A7: Mobile Augmented Reality Techniques for Emergency Response | B7: =IF(COUNTIF('Erin Accepted'!B:B, TRIM(SUBSTITUTE(A7, " ", ""))) > 0, "Accept", "Reject") -> Accept | C7: =IF(COUNTIF('Tanim Accepted'!B:B, TRIM(SUBSTITUTE(A7, " ", ""))) > 0, "Accept", "Reject") -> Accept | D7: =B7=C7 -> TRUE
A8: Training emergency responders through augmented reality mobile interfaces | B8: =IF(COUNTIF('Erin Accepted'!B:B, TRIM(SUBSTITUTE(A8, " ", ""))) > 0, "Accept", "Reject") -> Accept | C8: =IF(COUNTIF('Tanim Accepted'!B:B, TRIM(SUBSTITUTE(A8, " ", ""))) > 0, "Accept", "Reject") -> Accept | D8: =B8=C8 -> TRUE
A9: Design of Intelligent Firefighter Helmet Based on AR Technology | B9: =IF(COUNTIF('Erin Accepted'!B:B, TRIM(SUBSTITUTE(A9, " ", ""))) > 0, "Accept", "Reject") -> Accept | C9: =IF(COUNTIF('Tanim Accepted'!B:B, TRIM(SUBSTITUTE(A9, " ", ""))) > 0, "Accept", "Reject") -> Accept | D9: =B9=C9 -> TRUE
A10: Exploring the Design Space of Optical See-through AR Head-Mounted Displays to Support First Responders in the Field | B10: =IF(COUNTIF('Erin Accepted'!B:B, TRIM(SUBSTITUTE(A10, " ", ""))) > 0, "Accept", "Reject") -> Accept | C10: =IF(COUNTIF('Tanim Accepted'!B:B, TRIM(SUBSTITUTE(A10, " ", ""))) > 0, "Accept", "Reject") -> Accept | D10: =B10=C10 -> TRUE
A11: Augmented Reality for Real-time Decision-Making in Flood Emergencies | B11: Accept | C11: =IF(COUNTIF('Tanim Accepted'!B:B, TRIM(SUBSTITUTE(A11, " ", ""))) > 0, "Accept", "Reject") -> Accept | D11: =B11=C11 -> TRUE | E11: Came to consensus | F11: POI, water control, real time maps interfaces
A12: See through the Fire: Evaluating the Augmentation of Visual Perception of Firefighters Using Depth and Thermal Cameras | B12: Accept | C12: Accept | D12: =B12=C12 -> TRUE | E12: Tanim and I discussed; I do not remember the results of the discussion or why this is still marked as accepted. Did we mean to reject? The paper provides no context for interfaces developed -- only thermal and depth camera output. | F12: Related but no actual evidence of showing any results or demo
A13: AR Browser for Points of Interest in Disaster Response in UAV Imagery | B13: =IF(COUNTIF('Erin Accepted'!B:B, TRIM(SUBSTITUTE(A13, " ", ""))) > 0, "Accept", "Reject") -> Accept | C13: =IF(COUNTIF('Tanim Accepted'!B:B, TRIM(SUBSTITUTE(A13, " ", ""))) > 0, "Accept", "Reject") -> Accept | D13: =B13=C13 -> TRUE
A14: A Virtual and Augmented Reality Platform for the Training of First Responders of the Ambulance Bus | B14: Accept | C14: =IF(COUNTIF('Tanim Accepted'!B:B, TRIM(SUBSTITUTE(A14, " ", ""))) > 0, "Accept", "Reject") -> Accept | D14: =B14=C14 -> TRUE | E14: We have discussed previously, consensus was no as no interfaces developed for training in this paper were proposed for field | F14: Interactive training scenario, may need discussion | I14: Accept | J14: Paper to be included in final data, elements need to be addressed in paper
A15: SidebARs: Improving Awareness of off-Screen Elements in Mobile Augmented Reality | B15: =IF(COUNTIF('Erin Accepted'!B:B, TRIM(SUBSTITUTE(A15, " ", ""))) > 0, "Accept", "Reject") -> Accept | C15: =IF(COUNTIF('Tanim Accepted'!B:B, TRIM(SUBSTITUTE(A15, " ", ""))) > 0, "Accept", "Reject") -> Accept | D15: =B15=C15 -> TRUE
A16: A 'mixed reality' simulator concept for future Medical Emergency Response Team training | B16: =IF(COUNTIF('Erin Accepted'!B:B, TRIM(SUBSTITUTE(A16, " ", ""))) > 0, "Accept", "Reject") -> Accept | C16: =IF(COUNTIF('Tanim Accepted'!B:B, TRIM(SUBSTITUTE(A16, " ", ""))) > 0, "Accept", "Reject") -> Accept | D16: =B16=C16 -> TRUE
A17: Supporting first responder in-field communication and navigation using head-mounted displays | B17: =IF(COUNTIF('Erin Accepted'!B:B, TRIM(SUBSTITUTE(A17, " ", ""))) > 0, "Accept", "Reject") -> Accept | C17: =IF(COUNTIF('Tanim Accepted'!B:B, TRIM(SUBSTITUTE(A17, " ", ""))) > 0, "Accept", "Reject") -> Accept | D17: =B17=C17 -> TRUE
A18: Juxtopia®CAMMRAD Prepare: A Wearable AI-AR Platform for Clinical Training Emergency First Response Teams | B18: Accept | C18: =IF(COUNTIF('Tanim Accepted'!B:B, TRIM(SUBSTITUTE(A18, " ", ""))) > 0, "Accept", "Reject") -> Accept | D18: =B18=C18 -> TRUE | F18: Interactable training interface, might need discussion | I18: Accept | J18: Original review identified AIVR submission, include the SVR version instead
A19: Prehospital Pediatric Emergency Training Using Augmented Reality Simulation: A Prospective, Mixed Methods Study | B19: Accept | C19: =IF(COUNTIF('Tanim Accepted'!B:B, TRIM(SUBSTITUTE(A19, " ", ""))) > 0, "Accept", "Reject") -> Accept | D19: =B19=C19 -> TRUE | F19: Might need to discuss | I19: Accept | J19: Ensure the representation of training simulation in the final paper.
A20: Evaluation of an augmented reality platform for austere surgical telementoring: a randomized controlled crossover study in cricothyroidotomies | B20: =IF(COUNTIF('Erin Accepted'!B:B, TRIM(SUBSTITUTE(A20, " ", ""))) > 0, "Accept", "Reject") -> Accept | C20: =IF(COUNTIF('Tanim Accepted'!B:B, TRIM(SUBSTITUTE(A20, " ", ""))) > 0, "Accept", "Reject") -> Accept | D20: =B20=C20 -> TRUE
A21: Augmented reality and training for airway management procedures | B21: =IF(COUNTIF('Erin Accepted'!B:B, TRIM(SUBSTITUTE(A21, " ", ""))) > 0, "Accept", "Reject") -> Accept | C21: =IF(COUNTIF('Tanim Accepted'!B:B, TRIM(SUBSTITUTE(A21, " ", ""))) > 0, "Accept", "Reject") -> Accept | D21: =B21=C21 -> TRUE
A22: Augmented reality points of interest for improved first responder situational awareness | B22: =IF(COUNTIF('Erin Accepted'!B:B, TRIM(SUBSTITUTE(A22, " ", ""))) > 0, "Accept", "Reject") -> Accept | C22: =IF(COUNTIF('Tanim Accepted'!B:B, TRIM(SUBSTITUTE(A22, " ", ""))) > 0, "Accept", "Reject") -> Accept | D22: =B22=C22 -> TRUE
A23: Viability of Augmented Content for Field Policing | B23: =IF(COUNTIF('Erin Accepted'!B:B, TRIM(SUBSTITUTE(A23, " ", ""))) > 0, "Accept", "Reject") -> Accept | C23: =IF(COUNTIF('Tanim Accepted'!B:B, TRIM(SUBSTITUTE(A23, " ", ""))) > 0, "Accept", "Reject") -> Accept | D23: =B23=C23 -> TRUE
A24: Augmented reality based criminal investigation system (ARCRIME) | B24: =IF(COUNTIF('Erin Accepted'!B:B, TRIM(SUBSTITUTE(A24, " ", ""))) > 0, "Accept", "Reject") -> Accept | C24: =IF(COUNTIF('Tanim Accepted'!B:B, TRIM(SUBSTITUTE(A24, " ", ""))) > 0, "Accept", "Reject") -> Accept | D24: =B24=C24 -> TRUE
A25: Mixed Reality for Post-Disaster Situational Awareness | B25: =IF(COUNTIF('Erin Accepted'!B:B, TRIM(SUBSTITUTE(A25, " ", ""))) > 0, "Accept", "Reject") -> Accept | C25: =IF(COUNTIF('Tanim Accepted'!B:B, TRIM(SUBSTITUTE(A25, " ", ""))) > 0, "Accept", "Reject") -> Accept | D25: =B25=C25 -> TRUE
A26: Human-in-the-Loop Robot-Augmented Intelligent System for Emergency Reconnaissance | B26: =IF(COUNTIF('Erin Accepted'!B:B, TRIM(SUBSTITUTE(A26, " ", ""))) > 0, "Accept", "Reject") -> Accept | C26: =IF(COUNTIF('Tanim Accepted'!B:B, TRIM(SUBSTITUTE(A26, " ", ""))) > 0, "Accept", "Reject") -> Accept | D26: =B26=C26 -> TRUE
A27: Object detection and augmented reality annotations for increased situational awareness in light smoke conditions | B27: =IF(COUNTIF('Erin Accepted'!B:B, TRIM(SUBSTITUTE(A27, " ", ""))) > 0, "Accept", "Reject") -> Accept | C27: =IF(COUNTIF('Tanim Accepted'!B:B, TRIM(SUBSTITUTE(A27, " ", ""))) > 0, "Accept", "Reject") -> Accept | D27: =B27=C27 -> TRUE
A28: Real-Time Adaptation of Con-Aware Intelligent User Interfaces, for Enhanced Situational Awareness | B28: Reject | C28: Reject | D28: =B28=C28 -> TRUE | E28: Duplicated | F28: Duplicated | J28: Duplicated, remove this row from final results and keep original hit
A29: Augmented reality in law enforcement from an EU data protection law perspective: The darlene project as a case study | B29: Accept | C29: =IF(COUNTIF('Tanim Accepted'!B:B, TRIM(SUBSTITUTE(A29, " ", ""))) > 0, "Accept", "Reject") -> Accept | D29: =B29=C29 -> TRUE
A30: Seeing through Disaster Rubble in 3D with Ground-Penetrating Radar and Interactive Augmented Reality for Urban Search and Rescue | B30: =IF(COUNTIF('Erin Accepted'!B:B, TRIM(SUBSTITUTE(A30, " ", ""))) > 0, "Accept", "Reject") -> Accept | C30: =IF(COUNTIF('Tanim Accepted'!B:B, TRIM(SUBSTITUTE(A30, " ", ""))) > 0, "Accept", "Reject") -> Accept | D30: =B30=C30 -> TRUE
A31: Implementing user-centered methods and virtual reality to rapidly prototype augmented reality tools for firefighters | B31: =IF(COUNTIF('Erin Accepted'!B:B, TRIM(SUBSTITUTE(A31, " ", ""))) > 0, "Accept", "Reject") -> Accept | C31: =IF(COUNTIF('Tanim Accepted'!B:B, TRIM(SUBSTITUTE(A31, " ", ""))) > 0, "Accept", "Reject") -> Accept | D31: =B31=C31 -> TRUE
A32: An augmented reality application to support deployed emergency teams | B32: =IF(COUNTIF('Erin Accepted'!B:B, TRIM(SUBSTITUTE(A32, " ", ""))) > 0, "Accept", "Reject") -> Accept | C32: =IF(COUNTIF('Tanim Accepted'!B:B, TRIM(SUBSTITUTE(A32, " ", ""))) > 0, "Accept", "Reject") -> Accept | D32: =B32=C32 -> TRUE
A33: CPR Emergency Assistance Through Mixed Reality Communication | B33: =IF(COUNTIF('Erin Accepted'!B:B, TRIM(SUBSTITUTE(A33, " ", ""))) > 0, "Accept", "Reject") -> Accept | C33: =IF(COUNTIF('Tanim Accepted'!B:B, TRIM(SUBSTITUTE(A33, " ", ""))) > 0, "Accept", "Reject") -> Accept | D33: =B33=C33 -> TRUE
A34: Training and supporting first responders by mixed reality environments | B34: =IF(COUNTIF('Erin Accepted'!B:B, TRIM(SUBSTITUTE(A34, " ", ""))) > 0, "Accept", "Reject") -> Accept | C34: =IF(COUNTIF('Tanim Accepted'!B:B, TRIM(SUBSTITUTE(A34, " ", ""))) > 0, "Accept", "Reject") -> Accept | D34: =B34=C34 -> TRUE
A35: Augmented Reality Interface for Adverse-Visibility Conditions Validated by First Responders in Rescue Training Scenarios | B35: Accept | C35: Accept | D35: =B35=C35 -> TRUE | F35: Related to topic with interfaces and thermal camera feedback for data rendering
A36: Augmented Reality in Support of Disaster Response | B36: =IF(COUNTIF('Erin Accepted'!B:B, TRIM(SUBSTITUTE(A36, " ", ""))) > 0, "Accept", "Reject") -> Accept | C36: =IF(COUNTIF('Tanim Accepted'!B:B, TRIM(SUBSTITUTE(A36, " ", ""))) > 0, "Accept", "Reject") -> Accept | D36: =B36=C36 -> TRUE
A37: Single-handed gesture UAV control and video feed AR visualization for first responders | B37: =IF(COUNTIF('Erin Accepted'!B:B, TRIM(SUBSTITUTE(A37, " ", ""))) > 0, "Accept", "Reject") -> Accept | C37: =IF(COUNTIF('Tanim Accepted'!B:B, TRIM(SUBSTITUTE(A37, " ", ""))) > 0, "Accept", "Reject") -> Accept | D37: =B37=C37 -> TRUE
A38: An augmented reality system for health care provision via telematics support | B38: =IF(COUNTIF('Erin Accepted'!B:B, TRIM(SUBSTITUTE(A38, " ", ""))) > 0, "Accept", "Reject") -> Accept | C38: =IF(COUNTIF('Tanim Accepted'!B:B, TRIM(SUBSTITUTE(A38, " ", ""))) > 0, "Accept", "Reject") -> Accept | D38: =B38=C38 -> TRUE
A39: A robotic augmented reality virtual window for law enforcement operations | B39: =IF(COUNTIF('Erin Accepted'!B:B, TRIM(SUBSTITUTE(A39, " ", ""))) > 0, "Accept", "Reject") -> Accept | C39: =IF(COUNTIF('Tanim Accepted'!B:B, TRIM(SUBSTITUTE(A39, " ", ""))) > 0, "Accept", "Reject") -> Accept | D39: =B39=C39 -> TRUE
A40: Augmented Reality Technology to Facilitate Proficiency in Emergency Medical Procedures | B40: =IF(COUNTIF('Erin Accepted'!B:B, TRIM(SUBSTITUTE(A40, " ", ""))) > 0, "Accept", "Reject") -> Accept | C40: =IF(COUNTIF('Tanim Accepted'!B:B, TRIM(SUBSTITUTE(A40, " ", ""))) > 0, "Accept", "Reject") -> Accept | D40: =B40=C40 -> TRUE
...

Sheet Table for Paper
A1: Ref | B1: Title | C1: Authors | D1: Year | E1: Visual Output | F1: Auditory Output | G1: Haptic Output | H1: OST HMD | I1: VST HMD | J1: HMD (Unspecified) | K1: Mobile Device | L1: Other Display | M1: Field | N1: Control Room | O1: Training | P1: Others | Q1: EMS | R1: Firefighter | S1: Law Enforcement | T1: Other Discipline | U1: Physiological | V1: Patient/Suspect | W1: Environment | X1: Context Unaware | Y1: Spatial Context | Z1: HUD Context | AA1: Unreported Context | AB1: Interface Elements | AC1: Country | AD1: Conducted User Study? | AE1: Supports Use | AF1: Score??????????? | AG1: Data Collected | AH1: Notes
A2: \cite{antevski_5g-based_2021} | B2: A 5G-Based eHealth Monitoring and Emergency Response System: Experience and Lessons Learned | C2: Antevski et al. | D2: 2021 | E2: x | H2: x | M2: x | Q2: x | U2: x | W2: x | Y2: x | AB2: Points of Interest, Vitals Monitor | AC2: Italy | AD2: No
A3: \cite{arif_comparative_2019} | B3: A Comparative Study of Rendering Devices for Safety-Critical Applications in Operative Control Rooms | C3: Arif et al. | D3: 2019 | E3: x | H3: x | N3: x | R3: x | X3: x | Z3: x | AB3: 2D Map, Annotations | AC3: Austria, France, Spain, Slovakia | AD3: Yes | AE3: No | AF3: 0 | AG3: Usability, Preference
A4: \cite{azpiroz2024white} | B4: White Paper on Adaptive Situational Awareness Enhancing Augmented Reality Interface Design on First Responders in Rescue Tasks | C4: Azpiroz et al. | D4: 2024 | E4: x | H4: x | M4: x | R4: x | U4: x | W4: x | Z4: x | AB4: Radar, Augmented Enhancement | AC4: USA | AD4: No
A5: \cite{schmorrow_implementing_2016} | B5: Implementing user-centered methods and virtual reality to rapidly prototype augmented reality tools for firefighters | C5: Bailie et al. | D5: 2016 | E5: x | F5: x | I5: x | M5: x | R5: x | X5: x | Y5: x | Z5: x | AB5: Breadcrumbs, Navigation Arrow | AC5: USA | AD5: No
A6: \cite{balfour_what_2013} | B6: The what, why and how of achieving urban telepresence | C6: Balfour and Donnelly | D6: 2013 | E6: x | J6: x | L6: x | N6: x | Q6: x | R6: x | S6: x | X6: x | Y6: x | Z6: x | AB6: Augmented Enhancement | AC6: Germany | AD6: No
A7: \cite{berndt_optical_2015} | B7: Optical head-mounted displays in mass casualty incidents: Keeping an eye onpatients and hazardous materials | C7: Berndt et al. | D7: 2015 | E7: x | H7: x | M7: x | Q7: x | W7: x | Z7: x | AB7: Alert, Augmented Support | AC7: United Kingdom | AD7: No
A8: \cite{bhattarai_embedded_2020} | B8: An embedded deep learning system for augmented reality in firefighting applications | C8: Bhattarai et al. | D8: 2020 | E8: x | H8: x | M8: x | R8: x | W8: x | Y8: x | AB8: Object Highlighting | AC8: Brazil | AD8: No
A9: \cite{bram-larbi_collision_2020} | B9: Collision Avoidance Head-Up Display: Design Considerations for Emergency Services’ Vehicles | C9: Bram-Larbi et al. | D9: 2020 | E9: x | L9: x | M9: x | Q9: x | W9: x | Y9: x | AB9: Navigation Arrow | AC9: USA | AD9: No
A10: \cite{brandao_using_2017} | B10: Using augmented reality to improve dismounted operators' situation awareness | C10: Brandao and Pinho | D10: 2017 | E10: x | H10: x | M10: x | S10: x | X10: x | Y10: x | Z10: x | AB10: Navigation Line, Points of Interest, 2D Map, X-Ray, Spatial Reconstruction | AC10: USA | AD10: No
A11: \cite{broach_usability_nodate} | B11: Usability and reliability of smart glasses for secondary triage during mass casualty incidents | C11: Broach et al. | D11: 2018 | E11: x | H11: x | M11: x | Q11: x | X11: x | Z11: x | AB11: Annotations | AC11: Portugal | AD11: Yes | AE11: Yes | AF11: 1 | AG11: Usability, Reliability
A12: \cite{cai_mobile_2023} | B12: Mobile Incident Command Dashboard (MIS-D) | C12: Cai and Siegel | D12: 2023 | E12: x | H12: x | I12: x | K12: x | M12: x | Q12: x | R12: x | S12: x | W12: x | Y12: x | AB12: 3D Map, 2D Map, Points of Interest | AC12: Korea | AD12: No
A13: \cite{campos_mobile_2019} | B13: Mobile Augmented Reality Techniques for Emergency Response | C13: Campos et al. | D13: 2019 | E13: x | K13: x | M13: x | Q13: x | R13: x | S13: x | W13: x | Y13: x | Z13: x | AB13: Points of Interest, 2D Map, Radar | AC13: Greece | AD13: Yes | AE13: Yes | AF13: 1 | AG13: Usability
A14: \cite{chae_design_2023} | B14: Design of a Mixed Reality System for Simulating Indoor Disaster Rescue | C14: Chae et al. | D14: 2023 | E14: x | H14: x | M14: x | R14: x | W14: x | Y14: x | Z14: x | AB14: 2D Map, Navigation Arrow, X-Ray, Points of Interest | AC14: Canada | AD14: Yes | AE14: Yes | AF14: 1 | AG14: Time
A15: \cite{chalimas_cross-device_2023} | B15: Cross-Device Augmented Reality Systems for Fire and Rescue based on Thermal Imaging and Live Tracking | C15: Chalimas and Mania | D15: 2023 | E15: x | H15: x | M15: x | R15: x | W15: x | Y15: x | Z15: x | AB15: 2D Map, Navigation Arrow, Compass | AC15: USA | AD15: No
A16: \cite{chan_erwear_2016} | B16: ERWear: Wearable System Design through the Lens of First Responders | C16: Chan et al. | D16: 2016 | E16: x | H16: x | M16: x | Q16: x | R16: x | S16: x | W16: x | Z16: x | AB16: 2D Map, Points of Interest | AC16: China | AD16: No
A17: \cite{cheng_effective_2023} | B17: Effective Navigation for an Emergency Response for Firefighters with Wearable Haptic Displays Design | C17: Cheng et al. | D17: 2023 | E17: x | G17: x | H17: x | M17: x | R17: x | W17: x | Y17: x | Z17: x | AB17: 2D Map, Points of Interest, Annotations, Object Highlighting, Alert | AC17: Not Reported | AD17: No
A18: \cite{christaki_augmented_2022} | B18: Augmented reality points of interest for improved first responder situational awareness | C18: Christaki et al. | D18: 2022 | E18: x | H18: x | M18: x | Q18: x | R18: x | S18: x | X18: x | Y18: x | AB18: 2D Map, Points of Interest, On Demand Menu, Breadcrumbs, Live Video Feed, Navigation Arrow, Augmented Enhancement | AC18: Greece, France | AD18: No | AH18: Field trial conducted, no formal user study
A19: \cite{christian_google_2014} | B19: Google glass for public safety: Leveraging Google Glass for automatic information retrieval and notification by public safety officers in the field | C19: Christian et al. | D19: 2014 | E19: x | H19: x | M19: x | S19: x | V19: x | Z19: x | AB19: Alert | AC19: USA | AD19: No
A20: \cite{chroust2009training} | B20: Training and supporting first responders by mixed reality environments | C20: Chroust et al. | D20: 2009 | E20: x | J20: x | M20: x | Q20: x | R20: x | S20: x | W20: x | Y20: x | AB20: Points of Interest | AC20: Australia | AD20: No
A21: \cite{crowley_ar_2014} | B21: AR Browser for Points of Interest in Disaster Response in UAV Imagery | C21: Crowley et al. | D21: 2014 | E21: x | K21: x | M21: x | Q21: x | R21: x | S21: x | W21: x | Y21: x | Z21: x | AB21: 2D Map, Points of Interest | AC21: USA | AD21: No
A22: \cite{dave_augmenting_2013} | B22: Augmenting situational awareness for first responders using social media as a sensor | C22: Dave et al. | D22: 2013 | E22: x | K22: x | L22: x | M22: x | Q22: x | R22: x | S22: x | W22: x | Y22: x | AB22: Points of Interest | AC22: USA | AD22: No
A23: \cite{davis2002augmented} | B23: Augmented reality and training for airway management procedures | C23: Davis et al. | D23: 2002 | E23: x | J23: x | L23: x | M23: x | Q23: x | W23: x | Y23: x | AB23: X-Ray | AC23: USA | AD23: No
A24: \cite{demirkan_underground_2024} | B24: Underground mine emergency evacuation planning: AR implementation and casestudy | C24: Demirkan et al. | D24: 2024 | E24: x | H24: x | M24: x | Q24: x | R24: x | S24: x | W24: x | Y24: x | AB24: Edge Detection | AC24: USA | AD24: Yes | AE24: Yes | AF24: 1
A25: \cite{dianxi_design_2021} | B25: Design of Intelligent Firefighter Helmet Based on AR Technology | C25: Dianxi et al. | D25: 2021 | E25: x | J25: x | M25: x | R25: x | W25: x | Y25: x | AB25: Edge Detection | AC25: USA | AD25: No
A26: \cite{doswell2020juxtopia} | B26: Juxtopia®CAMMRAD Prepare: A Wearable AI-AR Platform for Clinical Training Emergency First Response Teams | C26: Doswell et al. | D26: 2020 | E26: x | H26: x | O26: x | Q26: x | X26: x | Y26: x | Z26: x | AB26: Augmented Support | AC26: Netherlands | AD26: No | AH26: Focus group only
A27: \cite{engelbrecht_viability_2018} | B27: Viability of Augmented Content for Field Policing | C27: Engelbrecht and Lukosch | D27: 2018 | E27: x | K27: x | M27: x | S27: x | V27: x | W27: x | Y27: x | AB27: Points of Interest, Alert | AC27: USA | AD27: No | AH27: Heuristic evaluation, not rigorously conducted or reported
A28: \cite{del2014red} | B28: Red Cross Triage App Design for Augmented Reality Glasses | C28: Fernández et al. | D28: 2014 | E28: x | H28: x | M28: x | Q28: x | W28: x | Y28: x | AB28: 2D Map, Augmented Support | AC28: Germany | AD28: No | AH28: Not rigorously reported
A29: \cite{follmann2019technical} | B29: Technical support by smart glasses during a mass casualty incident: A randomized controlled simulation trial on technically assisted triage and telemedical app use in disaster medicine | C29: Follmann et al. | D29: 2019 | E29: x | F29: x | H29: x | M29: x | Q29: x | X29: x | Z29: x | AB29: Augmented Support | AC29: USA | AD29: Yes | AE29: Yes Accuracy, No Time | AF29: 0.5 | AG29: Time, Accuracy
A30: \cite{friedman2024prehospital} | B30: Prehospital Pediatric Emergency Training Using Augmented Reality Simulation: A Prospective, Mixed Methods Study | C30: Friedman et al. | D30: 2024 | E30: x | H30: x | O30: x | Q30: x | V30: x | Y30: x | AB30: Augmented Enhancement | AC30: Spain | AD30: Yes | AE30: Yes | AF30: 1 | AG30: Usability
A31: \cite{garcia_health-5g_2023} | B31: Health-5G: A Mixed Reality-Based System for Remote Medical Assistance in Emergency Situations | C31: García et al. | D31: 2023 | E31: x | F31: x | H31: x | M31: x | Q31: x | U31: x | Y31: x | Z31: x | AB31: Vitals Monitor, On Demand Menu, Augmented Enhancement, Augmented Support | AC31: Germany, Spain, France | AD31: No | AH31: System performance analyzed
A32: \cite{garcia2024smart} | B32: Smart Helmet: Combining Sensors, AI, Augmented Reality, and Personal Protection to Enhance First Responders' Situational Awareness | C32: García et al. | D32: 2024 | E32: x | H32: x | M32: x | R32: x | U32: x | W32: x | Y32: x | Z32: x | AB32: Object Highlighting, Augmented Enhancement, Radar | AC32: Greece, Germany, Spain | AD32: Yes | AE32: Yes | AF32: 1 | AG32: Usability, Performance
A33: \cite{gkika_object_2023} | B33: Object detection and augmented reality annotations for increased situational awareness in light smoke conditions | C33: Gkika et al. | D33: 2023 | E33: x | H33: x | M33: x | R33: x | W33: x | Y33: x | AB33: Object Highlighting | AC33: USA | AD33: No | AH33: Not rigorously reported
A34: \cite{grandi_design_2021} | B34: Design and Simulation of Next-Generation Augmented Reality User Interfaces in Virtual Reality | C34: Grandi et al. | D34: 2021 | E34: x | I34: x | M34: x | R34: x | S34: x | W34: x | Y34: x | Z34: x | AB34: On Demand Menu, Augmented Enhancement, Points of Interest, Alert, 2D Map, Navigation Line, X-Ray, Object Highlighting, Annotations | AC34: USA | AD34: No
A35: \cite{grandi_simulating_2020} | B35: Simulating Next-Generation User Interfaces for Law Enforcement Traffic Stops | C35: Grandi et al. | D35: 2020 | E35: x | G35: x | I35: x | M35: x | S35: x | V35: x | W35: x | Y35: x | AB35: Augmented Enhancement, Object Highlighting, On Demand Display, Alert | AC35: Greece | AD35: No
A36: \cite{arregui_augmented_2022} | B36: An Augmented Reality Framework for First Responders: the RESPOND-A project approach | C36: Grigoriou et al. | D36: 2022 | E36: x | H36: x | M36: x | Q36: x | R36: x | S36: x | V36: x | W36: x | Y36: x | Z36: x | AB36: Alert, Annotations, Points of Interest, 2D Map | AC36: Pakistan | AD36: No
A37: \cite{haque_augmented_2020} | B37: Augmented reality based criminal investigation system (ARCRIME) | C37: Haque and Saleem | D37: 2020 | E37: x | F37: x | H37: x | K37: x | M37: x | S37: x | V37: x | W37: x | Y37: x | Z37: x | AB37: Points of Interest, Object Highlighting, Annotations | AC37: USA | AD37: No
A38: \cite{ii_mixed_2020} | B38: Mixed Reality for Post-Disaster Situational Awareness | C38: Howard et al. | D38: 2020 | E38: x | H38: x | M38: x | Q38: x | R38: x | S38: x | W38: x | Y38: x | AB38: Spatial Reconstruction | AC38: USA | AD38: No
A39: \cite{hu2021human} | B39: Human-in-the-Loop Robot-Augmented Intelligent System for Emergency Reconnaissance | C39: Hu et al. | D39: 2021 | E39: x | I39: x | M39: x | Q39: x | R39: x | S39: x | X39: x | Y39: x | AB39: Object Highlighting, Augmented Enhancement, Annotations, Points of Interest | AC39: Not Reported | AD39: Yes | AE39: Yes Time, Yes False Positives, No False Negatives | AF39: 0.5 | AG39: Time, False Positives, False Negatives
A40: \cite{hu_seeing_nodate} | B40: Seeing through Disaster Rubble in 3D with Ground-Penetrating Radar and Interactive Augmented Reality for Urban Search and Rescue | C40: Hu et al. | D40: 2022 | E40: x | H40: x | I40: x | K40: x | M40: x | Q40: x | R40: x | S40: x | W40: x | Y40: x | AB40: Virtual Objects, Augmented Enhancement, Object Highlighting | AC40: Argentina | AD40: No
...
